يصبح الفرق واضحًا عندما ننظر إلى الكود داخل دالة.

يختلف السلوك إذا كان هناك "خروج" من `try..catch`.

على سبيل المثال ، عندما يكون هناك `return` داخل `try..catch`. يعمل `finally` في حالة *أي* خروج من `try..catch`, حتى عبر عبارة `return`: مباشرة بعد الانتهاء من `try..catch`,  ولكن قبل أن يحصل الكود الذي قمنا بالاتصال به على التحكم.

```js run
function f() {
  try {
    alert('إبدء');
*!*
    return "النتيجة";
*/!*
  } catch (e) {
    /// ...
  } finally {
    alert('نظف!');
  }
}

f(); // نظف!
```

...أو عندما يكون هناك `throw`, مثلما هو الحال هنا:

```js run
function f() {
  try {
    alert('إبدء');
    throw new Error("an error");
  } catch (e) {
    // ...
    if("can't handle the error") {
*!*
      throw e;
*/!*
    }

  } finally {
    alert('نظف!')
  }
}

f(); // نظف!
```

يضمن `finally` التنظيف. إذا وضعنا الكود في نهاية `f`, فلن يتم تشغيلها في هذه المواقف.
